<?xml version="1.0" ?>
<!-- =================================================================================== -->
<!-- |    This document was autogenerated by xacro from bebop.urdf.xacro               | -->
<!-- |    EDITING THIS FILE BY HAND IS NOT RECOMMENDED                                 | -->
<!-- =================================================================================== -->
<robot name="quadrotor">
  <link name="base_link">
    <inertial>
      <mass value="0.399"/>
      <origin xyz="0 0 0"/>
      <inertia ixx="0.01152" ixy="0.0" ixz="0.0" iyy="0.01152" iyz="0.0" izz="0.0218"/>
      <!-- Inertia from hector quadrotor, sorry! -->
    </inertial>
    <visual>
      <origin rpy="0 0 0" xyz="0 0 0"/>
      <geometry>
        <mesh filename="package://bebop_gazebo/meshes/bebop_model.stl"/>
      </geometry>
      <material name="blue">
        <color rgba="0 0.4 0.6 1"/>
      </material>
    </visual>
    <collision>
      <origin rpy="0 0 0" xyz="0 0 0"/>
      <geometry>
        <mesh filename="package://bebop_gazebo/meshes/bebop_model.stl"/>
      </geometry>
    </collision>
  </link>
  <link name="camera_base_link"/>
  <link name="camera_pan_link"/>
  <link name="camera_tilt_link"/>
  <link name="camera_optical"/>
  <joint name="base_link_joint" type="fixed">
    <origin rpy="0 0 0" xyz="0.1 0 0.0"/>
    <parent link="base_link"/>
    <child link="camera_base_link"/>
  </joint>
  <joint name="camera_pan_joint" type="revolute">
    <origin rpy="0 0 0" xyz="0 0 0"/>
    <parent link="camera_base_link"/>
    <child link="camera_pan_link"/>
    <axis xyz="0 0 1"/>
    <limit effort="50" lower="-0.6108652381980153" upper="0.6108652381980153" velocity="2.0"/>
  </joint>
  <joint name="camera_tilt_joint" type="revolute">
    <origin rpy="0 0 0" xyz="0 0 0"/>
    <parent link="camera_pan_link"/>
    <child link="camera_tilt_link"/>
    <axis xyz="0 1 0"/>
    <limit effort="50" lower="-0.6108652381980153" upper="0.6108652381980153" velocity="2.0"/>
  </joint>
  <joint name="camera_optical_joint" type="fixed">
    <origin rpy="-1.5707963267948966 0 -1.5707963267948966" xyz="0 0 0"/>
    <parent link="camera_tilt_link"/>
    <child link="camera_optical"/>
  </joint>
  <joint name="lidar_joint" type="fixed">
    <origin rpy="0 0 0" xyz="0 0 -0.9"/>
    <parent link="base_link"/>
    <child link="lidar_link"/>
    <axis xyz="0 0 0"/>
  </joint>
  <link name="lidar_link">
    <origin rpy="0 0 0" xyz="0 0 0.1"/>
    <inertial>
      <mass value="1e-5"/>
      <origin xyz="0 0 0"/>
      <inertia ixx="1e-6" ixy="0" ixz="0" iyy="1e-6" iyz="0.0" izz="1e-6"/>
    </inertial>
    <visual>
      <origin rpy="0 0 0" xyz="0 0 0"/>
      <geometry>
        <cylinder length="0.01" radius="0.01"/>
      </geometry>
    </visual>
    <!-- <collision name='lidar_link_collision'>
        <pose>0 0 0 0 0 0</pose>
        <geometry>
            <cylinder>
            <radius>0.01</radius>
            <length>0.01</length>
          </cylinder>
        </geometry>
      </collision> -->
  </link>
  <gazebo reference="lidar_link">
    <sensor name="laser" type="ray">
      <visualize>true</visualize>
      <always_on>true</always_on>
      <update_rate>10</update_rate>
      <ray>
        <scan>
          <horizontal>
            <samples>360</samples>
            <resolution>1.00000</resolution>
            <min_angle>0.000000</min_angle>
            <max_angle>6.280000</max_angle>
          </horizontal>
        </scan>
        <range>
          <min>0.120000</min>
          <max>1</max>
          <resolution>0.015000</resolution>
        </range>
      </ray>
      <plugin filename="libgazebo_ros_laser.so" name="laser_controller">
        <alwaysOn>true</alwaysOn>
        <updateRate>15.0</updateRate>
        <topicName>scan</topicName>
        <frameName>world</frameName>
      </plugin>
    </sensor>
  </gazebo>
  <gazebo reference="base_link">
    <material>Gazebo/Black</material>
  </gazebo>
  <gazebo reference="base_link">
    <plugin filename="libplugin.so" name="uav_control_plugin"/>
  </gazebo>
</robot>

